nohup: ignoring input
cuda.sh: line 1: ï»¿export: command not found
/home/wangyaoxiang/anaconda3/envs/lora/lib/python3.10/site-packages/bitsandbytes/cuda_setup/main.py:145: UserWarning: /home/wangyaoxiang/anaconda3/envs/lora did not contain ['libcudart.so', 'libcudart.so.11.0', 'libcudart.so.12.0'] as expected! Searching further paths...
  warn(msg)
/home/wangyaoxiang/anaconda3/envs/lora/lib/python3.10/site-packages/bitsandbytes/cuda_setup/main.py:145: UserWarning: WARNING: The following directories listed in your path were found to be non-existent: {PosixPath('/usr/local/cuda/lib')}
  warn(msg)
cuda is True

===================================BUG REPORT===================================
Welcome to bitsandbytes. For bug reports, please run

python -m bitsandbytes

 and submit this information together with your error trace to: https://github.com/TimDettmers/bitsandbytes/issues
================================================================================
bin /home/wangyaoxiang/anaconda3/envs/lora/lib/python3.10/site-packages/bitsandbytes/libbitsandbytes_cuda117.so
CUDA SETUP: CUDA runtime path found: /usr/local/cuda/lib64/libcudart.so
CUDA SETUP: Highest compute capability among GPUs detected: 8.0
CUDA SETUP: Detected CUDA version 117
CUDA SETUP: Loading binary /home/wangyaoxiang/anaconda3/envs/lora/lib/python3.10/site-packages/bitsandbytes/libbitsandbytes_cuda117.so...
Traceback (most recent call last):
  File "/home/wangyaoxiang/anaconda3/envs/lora/lib/python3.10/site-packages/torch/cuda/__init__.py", line 242, in _lazy_init
    queued_call()
  File "/home/wangyaoxiang/anaconda3/envs/lora/lib/python3.10/site-packages/torch/cuda/__init__.py", line 125, in _check_capability
    capability = get_device_capability(d)
  File "/home/wangyaoxiang/anaconda3/envs/lora/lib/python3.10/site-packages/torch/cuda/__init__.py", line 357, in get_device_capability
    prop = get_device_properties(device)
  File "/home/wangyaoxiang/anaconda3/envs/lora/lib/python3.10/site-packages/torch/cuda/__init__.py", line 375, in get_device_properties
    return _get_device_properties(device)  # type: ignore[name-defined]
RuntimeError: device >= 0 && device < num_gpus INTERNAL ASSERT FAILED at "../aten/src/ATen/cuda/CUDAContext.cpp":50, please report a bug to PyTorch. 

The above exception was the direct cause of the following exception:

Traceback (most recent call last):
  File "/home/wangyaoxiang/codes/alpaca-lora/cuda.py", line 19, in <module>
    from peft import (
  File "/home/wangyaoxiang/anaconda3/envs/lora/lib/python3.10/site-packages/peft/__init__.py", line 22, in <module>
    from .mapping import MODEL_TYPE_TO_PEFT_MODEL_MAPPING, PEFT_TYPE_TO_CONFIG_MAPPING, get_peft_config, get_peft_model
  File "/home/wangyaoxiang/anaconda3/envs/lora/lib/python3.10/site-packages/peft/mapping.py", line 16, in <module>
    from .peft_model import (
  File "/home/wangyaoxiang/anaconda3/envs/lora/lib/python3.10/site-packages/peft/peft_model.py", line 31, in <module>
    from .tuners import (
  File "/home/wangyaoxiang/anaconda3/envs/lora/lib/python3.10/site-packages/peft/tuners/__init__.py", line 21, in <module>
    from .lora import LoraConfig, LoraModel
  File "/home/wangyaoxiang/anaconda3/envs/lora/lib/python3.10/site-packages/peft/tuners/lora.py", line 40, in <module>
    import bitsandbytes as bnb
  File "/home/wangyaoxiang/anaconda3/envs/lora/lib/python3.10/site-packages/bitsandbytes/__init__.py", line 6, in <module>
    from . import cuda_setup, utils, research
  File "/home/wangyaoxiang/anaconda3/envs/lora/lib/python3.10/site-packages/bitsandbytes/research/__init__.py", line 2, in <module>
    from .autograd._functions import (
  File "/home/wangyaoxiang/anaconda3/envs/lora/lib/python3.10/site-packages/bitsandbytes/research/autograd/_functions.py", line 10, in <module>
    from bitsandbytes.autograd._functions import MatmulLtState, GlobalOutlierPooler
  File "/home/wangyaoxiang/anaconda3/envs/lora/lib/python3.10/site-packages/bitsandbytes/autograd/__init__.py", line 1, in <module>
    from ._functions import undo_layout, get_inverse_transform_indices
  File "/home/wangyaoxiang/anaconda3/envs/lora/lib/python3.10/site-packages/bitsandbytes/autograd/_functions.py", line 236, in <module>
    class MatmulLtState:
  File "/home/wangyaoxiang/anaconda3/envs/lora/lib/python3.10/site-packages/bitsandbytes/autograd/_functions.py", line 258, in MatmulLtState
    formatB = F.get_special_format_str()
  File "/home/wangyaoxiang/anaconda3/envs/lora/lib/python3.10/site-packages/bitsandbytes/functional.py", line 281, in get_special_format_str
    major, _minor = torch.cuda.get_device_capability()
  File "/home/wangyaoxiang/anaconda3/envs/lora/lib/python3.10/site-packages/torch/cuda/__init__.py", line 357, in get_device_capability
    prop = get_device_properties(device)
  File "/home/wangyaoxiang/anaconda3/envs/lora/lib/python3.10/site-packages/torch/cuda/__init__.py", line 371, in get_device_properties
    _lazy_init()  # will define _get_device_properties
  File "/home/wangyaoxiang/anaconda3/envs/lora/lib/python3.10/site-packages/torch/cuda/__init__.py", line 246, in _lazy_init
    raise DeferredCudaCallError(msg) from e
torch.cuda.DeferredCudaCallError: CUDA call failed lazily at initialization with error: device >= 0 && device < num_gpus INTERNAL ASSERT FAILED at "../aten/src/ATen/cuda/CUDAContext.cpp":50, please report a bug to PyTorch. 

CUDA call was originally invoked at:

['  File "/home/wangyaoxiang/codes/alpaca-lora/cuda.py", line 1, in <module>\n    import torch\n', '  File "<frozen importlib._bootstrap>", line 1027, in _find_and_load\n', '  File "<frozen importlib._bootstrap>", line 1006, in _find_and_load_unlocked\n', '  File "<frozen importlib._bootstrap>", line 688, in _load_unlocked\n', '  File "<frozen importlib._bootstrap_external>", line 883, in exec_module\n', '  File "<frozen importlib._bootstrap>", line 241, in _call_with_frames_removed\n', '  File "/home/wangyaoxiang/anaconda3/envs/lora/lib/python3.10/site-packages/torch/__init__.py", line 798, in <module>\n    _C._initExtension(manager_path())\n', '  File "<frozen importlib._bootstrap>", line 1027, in _find_and_load\n', '  File "<frozen importlib._bootstrap>", line 1006, in _find_and_load_unlocked\n', '  File "<frozen importlib._bootstrap>", line 688, in _load_unlocked\n', '  File "<frozen importlib._bootstrap_external>", line 883, in exec_module\n', '  File "<frozen importlib._bootstrap>", line 241, in _call_with_frames_removed\n', '  File "/home/wangyaoxiang/anaconda3/envs/lora/lib/python3.10/site-packages/torch/cuda/__init__.py", line 179, in <module>\n    _lazy_call(_check_capability)\n', '  File "/home/wangyaoxiang/anaconda3/envs/lora/lib/python3.10/site-packages/torch/cuda/__init__.py", line 177, in _lazy_call\n    _queued_calls.append((callable, traceback.format_stack()))\n']
